<sdf version='1.7'>
  <world name='default'>
    <light name='sun' type='directional'>
      <cast_shadows>1</cast_shadows>
      <pose>0 0 10 0 -0 0</pose>
      <diffuse>0.8 0.8 0.8 1</diffuse>
      <specular>0.2 0.2 0.2 1</specular>
      <attenuation>
        <range>1000</range>
        <constant>0.9</constant>
        <linear>0.01</linear>
        <quadratic>0.001</quadratic>
      </attenuation>
      <direction>-0.5 0.1 -0.9</direction>
      <spot>
        <inner_angle>0</inner_angle>
        <outer_angle>0</outer_angle>
        <falloff>0</falloff>
      </spot>
    </light>
    <model name='ground_plane'>
      <static>1</static>
      <link name='link'>
        <collision name='collision'>
          <geometry>
            <plane>
              <normal>0 0 1</normal>
              <size>100 100</size>
            </plane>
          </geometry>
          <surface>
            <friction>
              <ode>
                <mu>100</mu>
                <mu2>50</mu2>
              </ode>
              <torsional>
                <ode/>
              </torsional>
            </friction>
            <contact>
              <ode/>
            </contact>
            <bounce/>
          </surface>
          <max_contacts>10</max_contacts>
        </collision>
        <visual name='visual'>
          <cast_shadows>0</cast_shadows>
          <geometry>
            <plane>
              <normal>0 0 1</normal>
              <size>100 100</size>
            </plane>
          </geometry>
          <material>
            <script>
              <uri>file://media/materials/scripts/gazebo.material</uri>
              <name>Gazebo/Grey</name>
            </script>
          </material>
        </visual>
        <self_collide>0</self_collide>
        <enable_wind>0</enable_wind>
        <kinematic>0</kinematic>
      </link>
    </model>
    <gravity>0 0 -9.8</gravity>
    <magnetic_field>6e-06 2.3e-05 -4.2e-05</magnetic_field>
    <atmosphere type='adiabatic'/>
    <physics type='ode'>
      <max_step_size>0.001</max_step_size>
      <real_time_factor>1</real_time_factor>
      <real_time_update_rate>1000</real_time_update_rate>
    </physics>
    <scene>
      <ambient>0.4 0.4 0.4 1</ambient>
      <background>0.7 0.7 0.7 1</background>
      <shadows>1</shadows>
    </scene>
    <audio>
      <device>default</device>
    </audio>
    <wind/>
    <spherical_coordinates>
      <surface_model>EARTH_WGS84</surface_model>
      <latitude_deg>0</latitude_deg>
      <longitude_deg>0</longitude_deg>
      <elevation>0</elevation>
      <heading_deg>0</heading_deg>
    </spherical_coordinates>
    <model name='my_bot'>
      <link name='base_link'>
        <inertial>
          <pose>0.005882 0 0.403676 0 -0 0</pose>
          <mass>3.06</mass>
          <inertia>
            <ixx>0.184717</ixx>
            <ixy>0</ixy>
            <ixz>-0.00330882</ixz>
            <iyy>0.280012</iyy>
            <iyz>0</iyz>
            <izz>0.415309</izz>
          </inertia>
        </inertial>
        <collision name='base_link_fixed_joint_lump__chassis_link_collision'>
          <pose>0 0 0.4 0 -0 0</pose>
          <geometry>
            <box>
              <size>1 0.8 0.3</size>
            </box>
          </geometry>
          <surface>
            <contact>
              <ode/>
            </contact>
            <friction>
              <ode/>
              <torsional>
                <ode/>
              </torsional>
            </friction>
            <bounce/>
          </surface>
          <max_contacts>10</max_contacts>
        </collision>
        <collision name='base_link_fixed_joint_lump__lidar_post_collision_1'>
          <pose>0.3 0 0.575 0 -0 0</pose>
          <geometry>
            <cylinder>
              <length>0.15</length>
              <radius>0.01</radius>
            </cylinder>
          </geometry>
          <surface>
            <contact>
              <ode/>
            </contact>
            <friction>
              <ode/>
              <torsional>
                <ode/>
              </torsional>
            </friction>
            <bounce/>
          </surface>
          <max_contacts>10</max_contacts>
        </collision>
        <collision name='base_link_fixed_joint_lump__laser_frame_collision_2'>
          <pose>0.3 0 0.65 0 -0 0</pose>
          <geometry>
            <cylinder>
              <length>0.04</length>
              <radius>0.05</radius>
            </cylinder>
          </geometry>
          <surface>
            <contact>
              <ode/>
            </contact>
            <friction>
              <ode/>
              <torsional>
                <ode/>
              </torsional>
            </friction>
            <bounce/>
          </surface>
          <max_contacts>10</max_contacts>
        </collision>
        <visual name='base_link_fixed_joint_lump__chassis_link_visual'>
          <pose>0 0 0.4 0 -0 0</pose>
          <geometry>
            <box>
              <size>1 0.8 0.3</size>
            </box>
          </geometry>
          <material>
            <script>
              <name>Gazebo/White</name>
              <uri>file://media/materials/scripts/gazebo.material</uri>
            </script>
          </material>
        </visual>
        <visual name='base_link_fixed_joint_lump__lidar_post_visual_1'>
          <pose>0.3 0 0.575 0 -0 0</pose>
          <geometry>
            <cylinder>
              <length>0.15</length>
              <radius>0.01</radius>
            </cylinder>
          </geometry>
          <material>
            <script>
              <name>Gazebo/Grey</name>
              <uri>file://media/materials/scripts/gazebo.material</uri>
            </script>
          </material>
        </visual>
        <visual name='base_link_fixed_joint_lump__laser_frame_visual_2'>
          <pose>0.3 0 0.67 0 -0 0</pose>
          <geometry>
            <cylinder>
              <length>0.04</length>
              <radius>0.05</radius>
            </cylinder>
          </geometry>
          <material>
            <script>
              <name>Gazebo/Black</name>
              <uri>file://media/materials/scripts/gazebo.material</uri>
            </script>
          </material>
        </visual>
        <sensor name='laser' type='ray'>
          <visualize>1</visualize>
          <update_rate>20</update_rate>
          <ray>
            <scan>
              <horizontal>
                <samples>360</samples>
                <min_angle>-3.14</min_angle>
                <max_angle>3.14</max_angle>
                <resolution>1</resolution>
              </horizontal>
              <vertical>
                <samples>1</samples>
                <min_angle>0</min_angle>
                <max_angle>0</max_angle>
              </vertical>
            </scan>
            <range>
              <min>0.3</min>
              <max>12</max>
            </range>
          </ray>
          <plugin name='laser_controller' filename='libgazebo_ros_ray_sensor.so'>
            <ros>
              <argument>~/out:=scan</argument>
            </ros>
            <output_type>sensor_msgs/LaserScan</output_type>
            <frame_name>laser_frame</frame_name>
          </plugin>
          <pose>0.3 0 0.65 0 -0 0</pose>
        </sensor>
        <self_collide>0</self_collide>
        <enable_wind>0</enable_wind>
        <kinematic>0</kinematic>
      </link>
      <joint name='left_back_steering_joint' type='revolute'>
        <pose relative_to='base_link'>-0.5 0.4 0.25 0 -0 0</pose>
        <parent>base_link</parent>
        <child>left_back_steering_link</child>
        <axis>
          <xyz>0 0 1</xyz>
          <limit>
            <lower>-1e+16</lower>
            <upper>1e+16</upper>
          </limit>
          <dynamics>
            <spring_reference>0</spring_reference>
            <spring_stiffness>0</spring_stiffness>
          </dynamics>
        </axis>
      </joint>
      <link name='left_back_steering_link'>
        <pose relative_to='left_back_steering_joint'>0 0 0 0 -0 0</pose>
        <inertial>
          <pose>0 0 0 0 -0 0</pose>
          <mass>0.25</mass>
          <inertia>
            <ixx>0.0025</ixx>
            <ixy>0</ixy>
            <ixz>0</ixz>
            <iyy>0.0025</iyy>
            <iyz>0</iyz>
            <izz>0.00125</izz>
          </inertia>
        </inertial>
        <collision name='left_back_steering_link_collision'>
          <pose>0 0 0 0 -0 0</pose>
          <geometry>
            <cylinder>
              <length>0.3</length>
              <radius>0.1</radius>
            </cylinder>
          </geometry>
          <surface>
            <contact>
              <ode/>
            </contact>
            <friction>
              <ode/>
              <torsional>
                <ode/>
              </torsional>
            </friction>
            <bounce/>
          </surface>
          <max_contacts>10</max_contacts>
        </collision>
        <visual name='left_back_steering_link_visual'>
          <pose>0 0 0 0 -0 0</pose>
          <geometry>
            <cylinder>
              <length>0.3</length>
              <radius>0.1</radius>
            </cylinder>
          </geometry>
          <material>
            <script>
              <name>Gazebo/Red</name>
              <uri>file://media/materials/scripts/gazebo.material</uri>
            </script>
          </material>
        </visual>
        <self_collide>0</self_collide>
        <enable_wind>0</enable_wind>
        <kinematic>0</kinematic>
      </link>
      <joint name='left_back_wheel_joint' type='revolute'>
        <pose relative_to='left_back_steering_link'>0 0 -0.15 -1.5708 0 0</pose>
        <parent>left_back_steering_link</parent>
        <child>left_back_wheel_link</child>
        <axis>
          <xyz>0 0 1</xyz>
          <limit>
            <lower>-1e+16</lower>
            <upper>1e+16</upper>
          </limit>
          <dynamics>
            <spring_reference>0</spring_reference>
            <spring_stiffness>0</spring_stiffness>
          </dynamics>
        </axis>
      </joint>
      <link name='left_back_wheel_link'>
        <pose relative_to='left_back_wheel_joint'>0 0 0 0 -0 0</pose>
        <inertial>
          <pose>0 0 0 0 -0 0</pose>
          <mass>0.5</mass>
          <inertia>
            <ixx>0.00447917</ixx>
            <ixy>0</ixy>
            <ixz>0</ixz>
            <iyy>0.00447917</iyy>
            <iyz>0</iyz>
            <izz>0.005625</izz>
          </inertia>
        </inertial>
        <collision name='left_back_wheel_link_collision'>
          <pose>0 0 0 0 -0 0</pose>
          <geometry>
            <cylinder>
              <length>0.2</length>
              <radius>0.15</radius>
            </cylinder>
          </geometry>
          <surface>
            <contact>
              <ode/>
            </contact>
            <friction>
              <ode/>
              <torsional>
                <ode/>
              </torsional>
            </friction>
            <bounce/>
          </surface>
          <max_contacts>10</max_contacts>
        </collision>
        <visual name='left_back_wheel_link_visual'>
          <pose>0 0 0 0 -0 0</pose>
          <geometry>
            <cylinder>
              <length>0.2</length>
              <radius>0.15</radius>
            </cylinder>
          </geometry>
          <material>
            <script>
              <name>Gazebo/Black</name>
              <uri>file://media/materials/scripts/gazebo.material</uri>
            </script>
          </material>
        </visual>
        <self_collide>0</self_collide>
        <enable_wind>0</enable_wind>
        <kinematic>0</kinematic>
      </link>
      <joint name='left_front_steering_joint' type='revolute'>
        <pose relative_to='base_link'>0.5 0.4 0.25 0 -0 0</pose>
        <parent>base_link</parent>
        <child>left_front_steering_link</child>
        <axis>
          <xyz>0 0 1</xyz>
          <limit>
            <lower>-1e+16</lower>
            <upper>1e+16</upper>
          </limit>
          <dynamics>
            <spring_reference>0</spring_reference>
            <spring_stiffness>0</spring_stiffness>
          </dynamics>
        </axis>
      </joint>
      <link name='left_front_steering_link'>
        <pose relative_to='left_front_steering_joint'>0 0 0 0 -0 0</pose>
        <inertial>
          <pose>0 0 0 0 -0 0</pose>
          <mass>0.25</mass>
          <inertia>
            <ixx>0.0025</ixx>
            <ixy>0</ixy>
            <ixz>0</ixz>
            <iyy>0.0025</iyy>
            <iyz>0</iyz>
            <izz>0.00125</izz>
          </inertia>
        </inertial>
        <collision name='left_front_steering_link_collision'>
          <pose>0 0 0 0 -0 0</pose>
          <geometry>
            <cylinder>
              <length>0.3</length>
              <radius>0.1</radius>
            </cylinder>
          </geometry>
          <surface>
            <contact>
              <ode/>
            </contact>
            <friction>
              <ode/>
              <torsional>
                <ode/>
              </torsional>
            </friction>
            <bounce/>
          </surface>
          <max_contacts>10</max_contacts>
        </collision>
        <visual name='left_front_steering_link_visual'>
          <pose>0 0 0 0 -0 0</pose>
          <geometry>
            <cylinder>
              <length>0.3</length>
              <radius>0.1</radius>
            </cylinder>
          </geometry>
          <material>
            <script>
              <name>Gazebo/Red</name>
              <uri>file://media/materials/scripts/gazebo.material</uri>
            </script>
          </material>
        </visual>
        <self_collide>0</self_collide>
        <enable_wind>0</enable_wind>
        <kinematic>0</kinematic>
      </link>
      <joint name='left_front_wheel_joint' type='revolute'>
        <pose relative_to='left_front_steering_link'>0 0 -0.15 -1.5708 0 0</pose>
        <parent>left_front_steering_link</parent>
        <child>left_front_wheel_link</child>
        <axis>
          <xyz>0 0 1</xyz>
          <limit>
            <lower>-1e+16</lower>
            <upper>1e+16</upper>
          </limit>
          <dynamics>
            <spring_reference>0</spring_reference>
            <spring_stiffness>0</spring_stiffness>
          </dynamics>
        </axis>
      </joint>
      <link name='left_front_wheel_link'>
        <pose relative_to='left_front_wheel_joint'>0 0 0 0 -0 0</pose>
        <inertial>
          <pose>0 0 0 0 -0 0</pose>
          <mass>0.5</mass>
          <inertia>
            <ixx>0.00447917</ixx>
            <ixy>0</ixy>
            <ixz>0</ixz>
            <iyy>0.00447917</iyy>
            <iyz>0</iyz>
            <izz>0.005625</izz>
          </inertia>
        </inertial>
        <collision name='left_front_wheel_link_collision'>
          <pose>0 0 0 0 -0 0</pose>
          <geometry>
            <cylinder>
              <length>0.2</length>
              <radius>0.15</radius>
            </cylinder>
          </geometry>
          <surface>
            <contact>
              <ode/>
            </contact>
            <friction>
              <ode/>
              <torsional>
                <ode/>
              </torsional>
            </friction>
            <bounce/>
          </surface>
          <max_contacts>10</max_contacts>
        </collision>
        <visual name='left_front_wheel_link_visual'>
          <pose>0 0 0 0 -0 0</pose>
          <geometry>
            <cylinder>
              <length>0.2</length>
              <radius>0.15</radius>
            </cylinder>
          </geometry>
          <material>
            <script>
              <name>Gazebo/Black</name>
              <uri>file://media/materials/scripts/gazebo.material</uri>
            </script>
          </material>
        </visual>
        <self_collide>0</self_collide>
        <enable_wind>0</enable_wind>
        <kinematic>0</kinematic>
      </link>
      <joint name='right_back_steering_joint' type='revolute'>
        <pose relative_to='base_link'>-0.5 -0.4 0.25 0 -0 0</pose>
        <parent>base_link</parent>
        <child>right_back_steering_link</child>
        <axis>
          <xyz>0 0 1</xyz>
          <limit>
            <lower>-1e+16</lower>
            <upper>1e+16</upper>
          </limit>
          <dynamics>
            <spring_reference>0</spring_reference>
            <spring_stiffness>0</spring_stiffness>
          </dynamics>
        </axis>
      </joint>
      <link name='right_back_steering_link'>
        <pose relative_to='right_back_steering_joint'>0 0 0 0 -0 0</pose>
        <inertial>
          <pose>0 0 0 0 -0 0</pose>
          <mass>0.25</mass>
          <inertia>
            <ixx>0.0025</ixx>
            <ixy>0</ixy>
            <ixz>0</ixz>
            <iyy>0.0025</iyy>
            <iyz>0</iyz>
            <izz>0.00125</izz>
          </inertia>
        </inertial>
        <collision name='right_back_steering_link_collision'>
          <pose>0 0 0 0 -0 0</pose>
          <geometry>
            <cylinder>
              <length>0.3</length>
              <radius>0.1</radius>
            </cylinder>
          </geometry>
          <surface>
            <contact>
              <ode/>
            </contact>
            <friction>
              <ode/>
              <torsional>
                <ode/>
              </torsional>
            </friction>
            <bounce/>
          </surface>
          <max_contacts>10</max_contacts>
        </collision>
        <visual name='right_back_steering_link_visual'>
          <pose>0 0 0 0 -0 0</pose>
          <geometry>
            <cylinder>
              <length>0.3</length>
              <radius>0.1</radius>
            </cylinder>
          </geometry>
          <material>
            <script>
              <name>Gazebo/Red</name>
              <uri>file://media/materials/scripts/gazebo.material</uri>
            </script>
          </material>
        </visual>
        <self_collide>0</self_collide>
        <enable_wind>0</enable_wind>
        <kinematic>0</kinematic>
      </link>
      <joint name='right_back_wheel_joint' type='revolute'>
        <pose relative_to='right_back_steering_link'>0 0 -0.15 -1.5708 0 0</pose>
        <parent>right_back_steering_link</parent>
        <child>right_back_wheel_link</child>
        <axis>
          <xyz>0 0 1</xyz>
          <limit>
            <lower>-1e+16</lower>
            <upper>1e+16</upper>
          </limit>
          <dynamics>
            <spring_reference>0</spring_reference>
            <spring_stiffness>0</spring_stiffness>
          </dynamics>
        </axis>
      </joint>
      <link name='right_back_wheel_link'>
        <pose relative_to='right_back_wheel_joint'>0 0 0 0 -0 0</pose>
        <inertial>
          <pose>0 0 0 0 -0 0</pose>
          <mass>0.5</mass>
          <inertia>
            <ixx>0.00447917</ixx>
            <ixy>0</ixy>
            <ixz>0</ixz>
            <iyy>0.00447917</iyy>
            <iyz>0</iyz>
            <izz>0.005625</izz>
          </inertia>
        </inertial>
        <collision name='right_back_wheel_link_collision'>
          <pose>0 0 0 0 -0 0</pose>
          <geometry>
            <cylinder>
              <length>0.2</length>
              <radius>0.15</radius>
            </cylinder>
          </geometry>
          <surface>
            <contact>
              <ode/>
            </contact>
            <friction>
              <ode/>
              <torsional>
                <ode/>
              </torsional>
            </friction>
            <bounce/>
          </surface>
          <max_contacts>10</max_contacts>
        </collision>
        <visual name='right_back_wheel_link_visual'>
          <pose>0 0 0 0 -0 0</pose>
          <geometry>
            <cylinder>
              <length>0.2</length>
              <radius>0.15</radius>
            </cylinder>
          </geometry>
          <material>
            <script>
              <name>Gazebo/Black</name>
              <uri>file://media/materials/scripts/gazebo.material</uri>
            </script>
          </material>
        </visual>
        <self_collide>0</self_collide>
        <enable_wind>0</enable_wind>
        <kinematic>0</kinematic>
      </link>
      <joint name='right_front_steering_joint' type='revolute'>
        <pose relative_to='base_link'>0.5 -0.4 0.25 0 -0 0</pose>
        <parent>base_link</parent>
        <child>right_front_steering_link</child>
        <axis>
          <xyz>0 0 1</xyz>
          <limit>
            <lower>-1e+16</lower>
            <upper>1e+16</upper>
          </limit>
          <dynamics>
            <spring_reference>0</spring_reference>
            <spring_stiffness>0</spring_stiffness>
          </dynamics>
        </axis>
      </joint>
      <link name='right_front_steering_link'>
        <pose relative_to='right_front_steering_joint'>0 0 0 0 -0 0</pose>
        <inertial>
          <pose>0 0 0 0 -0 0</pose>
          <mass>0.25</mass>
          <inertia>
            <ixx>0.0025</ixx>
            <ixy>0</ixy>
            <ixz>0</ixz>
            <iyy>0.0025</iyy>
            <iyz>0</iyz>
            <izz>0.00125</izz>
          </inertia>
        </inertial>
        <collision name='right_front_steering_link_collision'>
          <pose>0 0 0 0 -0 0</pose>
          <geometry>
            <cylinder>
              <length>0.3</length>
              <radius>0.1</radius>
            </cylinder>
          </geometry>
          <surface>
            <contact>
              <ode/>
            </contact>
            <friction>
              <ode/>
              <torsional>
                <ode/>
              </torsional>
            </friction>
            <bounce/>
          </surface>
          <max_contacts>10</max_contacts>
        </collision>
        <visual name='right_front_steering_link_visual'>
          <pose>0 0 0 0 -0 0</pose>
          <geometry>
            <cylinder>
              <length>0.3</length>
              <radius>0.1</radius>
            </cylinder>
          </geometry>
          <material>
            <script>
              <name>Gazebo/Red</name>
              <uri>file://media/materials/scripts/gazebo.material</uri>
            </script>
          </material>
        </visual>
        <self_collide>0</self_collide>
        <enable_wind>0</enable_wind>
        <kinematic>0</kinematic>
      </link>
      <joint name='right_front_wheel_joint' type='revolute'>
        <pose relative_to='right_front_steering_link'>0 0 -0.15 -1.5708 0 0</pose>
        <parent>right_front_steering_link</parent>
        <child>right_front_wheel_link</child>
        <axis>
          <xyz>0 0 1</xyz>
          <limit>
            <lower>-1e+16</lower>
            <upper>1e+16</upper>
          </limit>
          <dynamics>
            <spring_reference>0</spring_reference>
            <spring_stiffness>0</spring_stiffness>
          </dynamics>
        </axis>
      </joint>
      <link name='right_front_wheel_link'>
        <pose relative_to='right_front_wheel_joint'>0 0 0 0 -0 0</pose>
        <inertial>
          <pose>0 0 0 0 -0 0</pose>
          <mass>0.5</mass>
          <inertia>
            <ixx>0.00447917</ixx>
            <ixy>0</ixy>
            <ixz>0</ixz>
            <iyy>0.00447917</iyy>
            <iyz>0</iyz>
            <izz>0.005625</izz>
          </inertia>
        </inertial>
        <collision name='right_front_wheel_link_collision'>
          <pose>0 0 0 0 -0 0</pose>
          <geometry>
            <cylinder>
              <length>0.2</length>
              <radius>0.15</radius>
            </cylinder>
          </geometry>
          <surface>
            <contact>
              <ode/>
            </contact>
            <friction>
              <ode/>
              <torsional>
                <ode/>
              </torsional>
            </friction>
            <bounce/>
          </surface>
          <max_contacts>10</max_contacts>
        </collision>
        <visual name='right_front_wheel_link_visual'>
          <pose>0 0 0 0 -0 0</pose>
          <geometry>
            <cylinder>
              <length>0.2</length>
              <radius>0.15</radius>
            </cylinder>
          </geometry>
          <material>
            <script>
              <name>Gazebo/Black</name>
              <uri>file://media/materials/scripts/gazebo.material</uri>
            </script>
          </material>
        </visual>
        <self_collide>0</self_collide>
        <enable_wind>0</enable_wind>
        <kinematic>0</kinematic>
      </link>
      <static>0</static>
      <plugin name='gazebo_ros2_control' filename='libgazebo_ros2_control.so'>
        <parameters>/home/fuga1129/aurora_sim_v2/install/aurora_drive/share/aurora_drive/config/controller_4ws.yaml</parameters>
      </plugin>
      <pose>0 0 0 0 -0 0</pose>
    </model>
    <model name='Construction Cone'>
      <link name='link'>
        <collision name='collision'>
          <geometry>
            <mesh>
              <scale>10 10 10</scale>
              <uri>model://construction_cone/meshes/construction_cone.dae</uri>
            </mesh>
          </geometry>
          <max_contacts>10</max_contacts>
          <surface>
            <contact>
              <ode/>
            </contact>
            <bounce/>
            <friction>
              <torsional>
                <ode/>
              </torsional>
              <ode/>
            </friction>
          </surface>
        </collision>
        <visual name='visual'>
          <geometry>
            <mesh>
              <scale>10 10 10</scale>
              <uri>model://construction_cone/meshes/construction_cone.dae</uri>
            </mesh>
          </geometry>
        </visual>
        <self_collide>0</self_collide>
        <inertial>
          <pose>0 0 0 0 -0 0</pose>
          <inertia>
            <ixx>1</ixx>
            <ixy>0</ixy>
            <ixz>0</ixz>
            <iyy>1</iyy>
            <iyz>0</iyz>
            <izz>1</izz>
          </inertia>
          <mass>1</mass>
        </inertial>
        <enable_wind>0</enable_wind>
        <kinematic>0</kinematic>
      </link>
      <pose>0.026038 3.95601 0 0 -0 0</pose>
    </model>
    <model name='Construction Barrel'>
      <link name='link'>
        <inertial>
          <pose>0 0 0.4 0 -0 0</pose>
          <mass>500</mass>
          <inertia>
            <ixx>51.2096</ixx>
            <iyy>51.2096</iyy>
            <izz>25</izz>
            <ixy>0</ixy>
            <ixz>0</ixz>
            <iyz>0</iyz>
          </inertia>
        </inertial>
        <collision name='collision'>
          <geometry>
            <mesh>
              <uri>model://construction_barrel/meshes/construction_barrel.dae</uri>
            </mesh>
          </geometry>
          <max_contacts>10</max_contacts>
          <surface>
            <contact>
              <ode/>
            </contact>
            <bounce/>
            <friction>
              <torsional>
                <ode/>
              </torsional>
              <ode/>
            </friction>
          </surface>
        </collision>
        <visual name='visual'>
          <geometry>
            <mesh>
              <uri>model://construction_barrel/meshes/construction_barrel.dae</uri>
            </mesh>
          </geometry>
        </visual>
        <self_collide>0</self_collide>
        <enable_wind>0</enable_wind>
        <kinematic>0</kinematic>
      </link>
      <pose>2.17409 0.053173 0 0 -0 0</pose>
    </model>
    <model name='Construction Barrel_0'>
      <link name='link'>
        <inertial>
          <pose>0 0 0.4 0 -0 0</pose>
          <mass>500</mass>
          <inertia>
            <ixx>51.2096</ixx>
            <iyy>51.2096</iyy>
            <izz>25</izz>
            <ixy>0</ixy>
            <ixz>0</ixz>
            <iyz>0</iyz>
          </inertia>
        </inertial>
        <collision name='collision'>
          <geometry>
            <mesh>
              <uri>model://construction_barrel/meshes/construction_barrel.dae</uri>
            </mesh>
          </geometry>
          <max_contacts>10</max_contacts>
          <surface>
            <contact>
              <ode/>
            </contact>
            <bounce/>
            <friction>
              <torsional>
                <ode/>
              </torsional>
              <ode/>
            </friction>
          </surface>
        </collision>
        <visual name='visual'>
          <geometry>
            <mesh>
              <uri>model://construction_barrel/meshes/construction_barrel.dae</uri>
            </mesh>
          </geometry>
        </visual>
        <self_collide>0</self_collide>
        <enable_wind>0</enable_wind>
        <kinematic>0</kinematic>
      </link>
      <pose>-1.58162 1.54529 0 0 -0 0</pose>
    </model>
    <model name='Construction Cone_0'>
      <link name='link'>
        <collision name='collision'>
          <geometry>
            <mesh>
              <scale>10 10 10</scale>
              <uri>model://construction_cone/meshes/construction_cone.dae</uri>
            </mesh>
          </geometry>
          <max_contacts>10</max_contacts>
          <surface>
            <contact>
              <ode/>
            </contact>
            <bounce/>
            <friction>
              <torsional>
                <ode/>
              </torsional>
              <ode/>
            </friction>
          </surface>
        </collision>
        <visual name='visual'>
          <geometry>
            <mesh>
              <scale>10 10 10</scale>
              <uri>model://construction_cone/meshes/construction_cone.dae</uri>
            </mesh>
          </geometry>
        </visual>
        <self_collide>0</self_collide>
        <inertial>
          <pose>0 0 0 0 -0 0</pose>
          <inertia>
            <ixx>1</ixx>
            <ixy>0</ixy>
            <ixz>0</ixz>
            <iyy>1</iyy>
            <iyz>0</iyz>
            <izz>1</izz>
          </inertia>
          <mass>1</mass>
        </inertial>
        <enable_wind>0</enable_wind>
        <kinematic>0</kinematic>
      </link>
      <pose>-1.03264 -0.955663 0 0 -0 0</pose>
    </model>
    <model name='Construction Barrel_1'>
      <link name='link'>
        <inertial>
          <pose>0 0 0.4 0 -0 0</pose>
          <mass>500</mass>
          <inertia>
            <ixx>51.2096</ixx>
            <iyy>51.2096</iyy>
            <izz>25</izz>
            <ixy>0</ixy>
            <ixz>0</ixz>
            <iyz>0</iyz>
          </inertia>
        </inertial>
        <collision name='collision'>
          <geometry>
            <mesh>
              <uri>model://construction_barrel/meshes/construction_barrel.dae</uri>
            </mesh>
          </geometry>
          <max_contacts>10</max_contacts>
          <surface>
            <contact>
              <ode/>
            </contact>
            <bounce/>
            <friction>
              <torsional>
                <ode/>
              </torsional>
              <ode/>
            </friction>
          </surface>
        </collision>
        <visual name='visual'>
          <geometry>
            <mesh>
              <uri>model://construction_barrel/meshes/construction_barrel.dae</uri>
            </mesh>
          </geometry>
        </visual>
        <self_collide>0</self_collide>
        <enable_wind>0</enable_wind>
        <kinematic>0</kinematic>
      </link>
      <pose>0.941041 -1.50253 0 0 -0 0</pose>
    </model>
    <state world_name='default'>
      <sim_time>236 701000000</sim_time>
      <real_time>237 579242226</real_time>
      <wall_time>1765743835 784724375</wall_time>
      <iterations>236701</iterations>
      <model name='Construction Barrel'>
        <pose>2.17406 0.053164 -1e-06 3e-06 1e-05 -7e-06</pose>
        <scale>1 1 1</scale>
        <link name='link'>
          <pose>2.17406 0.053164 -1e-06 3e-06 1e-05 -7e-06</pose>
          <velocity>0 0 0 0 -0 0</velocity>
          <acceleration>2.398 4.10927 -3.69364 2.28589 -0.447096 0.22479</acceleration>
          <wrench>1199 2054.64 -1846.82 0 -0 0</wrench>
        </link>
      </model>
      <model name='Construction Barrel_0'>
        <pose>-1.58164 1.54528 1e-06 2e-06 3e-06 -6e-06</pose>
        <scale>1 1 1</scale>
        <link name='link'>
          <pose>-1.58164 1.54528 1e-06 2e-06 3e-06 -6e-06</pose>
          <velocity>0 0 0 0 -0 0</velocity>
          <acceleration>-4.02544 2.62102 -2.0324 2.85498 0.631685 -3.12435</acceleration>
          <wrench>-2012.72 1310.51 -1016.2 0 -0 0</wrench>
        </link>
      </model>
      <model name='Construction Barrel_1'>
        <pose>0.941031 -1.50253 -1e-06 3e-06 -2e-06 -2e-06</pose>
        <scale>1 1 1</scale>
        <link name='link'>
          <pose>0.941031 -1.50253 -1e-06 3e-06 -2e-06 -2e-06</pose>
          <velocity>0 0 0 0 -0 0</velocity>
          <acceleration>5.7256 -8.18842 8.25013 -1.44513 1.12853 3.02725</acceleration>
          <wrench>2862.8 -4094.21 4125.06 0 -0 0</wrench>
        </link>
      </model>
      <model name='Construction Cone'>
        <pose>0.026038 3.95601 -5e-06 -4e-06 1e-06 0</pose>
        <scale>1 1 1</scale>
        <link name='link'>
          <pose>0.026038 3.95601 -5e-06 -4e-06 1e-06 0</pose>
          <velocity>0 0 0 0 -0 0</velocity>
          <acceleration>0 0 -9.8 0 -0 0</acceleration>
          <wrench>0 0 -9.8 0 -0 0</wrench>
        </link>
      </model>
      <model name='Construction Cone_0'>
        <pose>-1.03264 -0.955663 -0 0 -0 0</pose>
        <scale>1 1 1</scale>
        <link name='link'>
          <pose>-1.03264 -0.955663 -0 0 -0 0</pose>
          <velocity>0 0 0 0 -0 0</velocity>
          <acceleration>0 -0 -0.008512 -2.58585 1.13682 3.14159</acceleration>
          <wrench>0 -0 -0.008512 0 -0 0</wrench>
        </link>
      </model>
      <model name='ground_plane'>
        <pose>0 0 0 0 -0 0</pose>
        <scale>1 1 1</scale>
        <link name='link'>
          <pose>0 0 0 0 -0 0</pose>
          <velocity>0 0 0 0 -0 0</velocity>
          <acceleration>0 0 0 0 -0 0</acceleration>
          <wrench>0 0 0 0 -0 0</wrench>
        </link>
      </model>
      <model name='my_bot'>
        <pose>0.00188 0.002597 0.050001 1e-06 -0 -0.003855</pose>
        <scale>1 1 1</scale>
        <link name='base_link'>
          <pose>0.00188 0.002597 0.050001 1e-06 -0 -0.003855</pose>
          <velocity>0 0 -1e-06 0 -0 0</velocity>
          <acceleration>-2e-06 -0 2e-06 0 0 -3e-06</acceleration>
          <wrench>-6e-06 -0 7e-06 0 -0 0</wrench>
        </link>
        <link name='left_back_steering_link'>
          <pose>-0.496575 0.404521 0.300001 -5e-06 0 -0.003851</pose>
          <velocity>-0 0 -1e-06 9e-06 -0 0</velocity>
          <acceleration>-4.5e-05 0.000244 -5.9e-05 0.008617 -3.9e-05 -0.000579</acceleration>
          <wrench>-1.1e-05 6.1e-05 -1.5e-05 0 -0 0</wrench>
        </link>
        <link name='left_back_wheel_link'>
          <pose>-0.496575 0.40452 0.150001 -1.57081 -0.012176 -0.003851</pose>
          <velocity>-0 1e-06 -1e-06 1.6e-05 -0 0</velocity>
          <acceleration>-1e-06 -0.0006 2e-06 0.007493 -0.000188 -4e-06</acceleration>
          <wrench>-1e-06 -0.0003 1e-06 0 -0 0</wrench>
        </link>
        <link name='left_front_steering_link'>
          <pose>0.503418 0.400666 0.300001 -5e-06 -0 -0.003858</pose>
          <velocity>-0 1e-06 -2e-06 9e-06 -0 0</velocity>
          <acceleration>5e-06 0.000253 -0.000157 0.009175 -3.2e-05 -0.000324</acceleration>
          <wrench>1e-06 6.3e-05 -3.9e-05 0 -0 0</wrench>
        </link>
        <link name='left_front_wheel_link'>
          <pose>0.503418 0.400666 0.150001 -1.57081 0.010699 -0.003858</pose>
          <velocity>-0 1e-06 -2e-06 1.8e-05 -0 0</velocity>
          <acceleration>-5e-06 -0.000655 2e-06 0.008194 -0.00013 -8e-06</acceleration>
          <wrench>-3e-06 -0.000327 1e-06 0 -0 0</wrench>
        </link>
        <link name='right_back_steering_link'>
          <pose>-0.499659 -0.395473 0.300001 6e-06 -0 -0.003851</pose>
          <velocity>0 -0 -1e-06 -9e-06 -0 -1e-06</velocity>
          <acceleration>-5.4e-05 -0.000373 0.000133 -0.009073 4.1e-05 -0.001263</acceleration>
          <wrench>-1.4e-05 -9.3e-05 3.3e-05 0 -0 0</wrench>
        </link>
        <link name='right_back_wheel_link'>
          <pose>-0.499658 -0.395472 0.150001 -1.57079 0.003273 -0.003851</pose>
          <velocity>0 -1e-06 -1e-06 -1.6e-05 -0 -1e-06</velocity>
          <acceleration>-2e-06 0.000599 2e-06 -0.007476 0.00037 4e-06</acceleration>
          <wrench>-1e-06 0.0003 1e-06 0 -0 0</wrench>
        </link>
        <link name='right_front_steering_link'>
          <pose>0.500334 -0.399328 0.300001 -1e-06 0 -0.003854</pose>
          <velocity>0 0 -2e-06 3e-06 -0 -1e-06</velocity>
          <acceleration>-3e-06 1e-05 3.8e-05 0.002602 -1.2e-05 -0.001549</acceleration>
          <wrench>-1e-06 3e-06 9e-06 0 -0 0</wrench>
        </link>
        <link name='right_front_wheel_link'>
          <pose>0.500334 -0.399327 0.150001 -1.57079 -0.000201 -0.003854</pose>
          <velocity>0 -1e-06 -2e-06 -1.8e-05 1e-06 -1e-06</velocity>
          <acceleration>-1e-05 -0.00159 4e-06 -0.02035 0.000482 4e-06</acceleration>
          <wrench>-5e-06 -0.000795 2e-06 0 -0 0</wrench>
        </link>
      </model>
      <light name='sun'>
        <pose>0 0 10 0 -0 0</pose>
      </light>
    </state>
    <gui fullscreen='0'>
      <camera name='user_camera'>
        <pose>-0.204806 -2.56198 26.2631 0 1.45964 1.5762</pose>
        <view_controller>orbit</view_controller>
        <projection_type>perspective</projection_type>
      </camera>
    </gui>
  </world>
</sdf>
