<sdf version='1.7'>
  <world name='default'>
    <light name='sun' type='directional'>
      <cast_shadows>1</cast_shadows>
      <pose>0 0 10 0 -0 0</pose>
      <diffuse>0.8 0.8 0.8 1</diffuse>
      <specular>0.2 0.2 0.2 1</specular>
      <attenuation>
        <range>1000</range>
        <constant>0.9</constant>
        <linear>0.01</linear>
        <quadratic>0.001</quadratic>
      </attenuation>
      <direction>-0.5 0.1 -0.9</direction>
      <spot>
        <inner_angle>0</inner_angle>
        <outer_angle>0</outer_angle>
        <falloff>0</falloff>
      </spot>
    </light>
    <model name='ground_plane'>
      <static>1</static>
      <link name='link'>
        <collision name='collision'>
          <geometry>
            <plane>
              <normal>0 0 1</normal>
              <size>100 100</size>
            </plane>
          </geometry>
          <surface>
            <friction>
              <ode>
                <mu>100</mu>
                <mu2>50</mu2>
              </ode>
              <torsional>
                <ode/>
              </torsional>
            </friction>
            <contact>
              <ode/>
            </contact>
            <bounce/>
          </surface>
          <max_contacts>10</max_contacts>
        </collision>
        <visual name='visual'>
          <cast_shadows>0</cast_shadows>
          <geometry>
            <plane>
              <normal>0 0 1</normal>
              <size>100 100</size>
            </plane>
          </geometry>
          <material>
            <script>
              <uri>file://media/materials/scripts/gazebo.material</uri>
              <name>Gazebo/Grey</name>
            </script>
          </material>
        </visual>
        <self_collide>0</self_collide>
        <enable_wind>0</enable_wind>
        <kinematic>0</kinematic>
      </link>
    </model>
    <gravity>0 0 -9.8</gravity>
    <magnetic_field>6e-06 2.3e-05 -4.2e-05</magnetic_field>
    <atmosphere type='adiabatic'/>
    <physics type='ode'>
      <max_step_size>0.001</max_step_size>
      <real_time_factor>1</real_time_factor>
      <real_time_update_rate>1000</real_time_update_rate>
    </physics>
    <scene>
      <ambient>0.4 0.4 0.4 1</ambient>
      <background>0.7 0.7 0.7 1</background>
      <shadows>1</shadows>
    </scene>
    <audio>
      <device>default</device>
    </audio>
    <wind/>
    <spherical_coordinates>
      <surface_model>EARTH_WGS84</surface_model>
      <latitude_deg>0</latitude_deg>
      <longitude_deg>0</longitude_deg>
      <elevation>0</elevation>
      <heading_deg>0</heading_deg>
    </spherical_coordinates>
    <model name='my_bot'>
      <link name='base_link'>
        <inertial>
          <pose>0.005882 0 0.403676 0 -0 0</pose>
          <mass>3.06</mass>
          <inertia>
            <ixx>0.184717</ixx>
            <ixy>0</ixy>
            <ixz>-0.00330882</ixz>
            <iyy>0.280012</iyy>
            <iyz>0</iyz>
            <izz>0.415309</izz>
          </inertia>
        </inertial>
        <collision name='base_link_fixed_joint_lump__chassis_link_collision'>
          <pose>0 0 0.4 0 -0 0</pose>
          <geometry>
            <box>
              <size>1 0.8 0.3</size>
            </box>
          </geometry>
          <surface>
            <contact>
              <ode/>
            </contact>
            <friction>
              <ode/>
              <torsional>
                <ode/>
              </torsional>
            </friction>
            <bounce/>
          </surface>
          <max_contacts>10</max_contacts>
        </collision>
        <collision name='base_link_fixed_joint_lump__lidar_post_collision_1'>
          <pose>0.3 0 0.575 0 -0 0</pose>
          <geometry>
            <cylinder>
              <length>0.15</length>
              <radius>0.01</radius>
            </cylinder>
          </geometry>
          <surface>
            <contact>
              <ode/>
            </contact>
            <friction>
              <ode/>
              <torsional>
                <ode/>
              </torsional>
            </friction>
            <bounce/>
          </surface>
          <max_contacts>10</max_contacts>
        </collision>
        <collision name='base_link_fixed_joint_lump__laser_frame_collision_2'>
          <pose>0.3 0 0.65 0 -0 0</pose>
          <geometry>
            <cylinder>
              <length>0.04</length>
              <radius>0.05</radius>
            </cylinder>
          </geometry>
          <surface>
            <contact>
              <ode/>
            </contact>
            <friction>
              <ode/>
              <torsional>
                <ode/>
              </torsional>
            </friction>
            <bounce/>
          </surface>
          <max_contacts>10</max_contacts>
        </collision>
        <visual name='base_link_fixed_joint_lump__chassis_link_visual'>
          <pose>0 0 0.4 0 -0 0</pose>
          <geometry>
            <box>
              <size>1 0.8 0.3</size>
            </box>
          </geometry>
          <material>
            <script>
              <name>Gazebo/White</name>
              <uri>file://media/materials/scripts/gazebo.material</uri>
            </script>
          </material>
        </visual>
        <visual name='base_link_fixed_joint_lump__lidar_post_visual_1'>
          <pose>0.3 0 0.575 0 -0 0</pose>
          <geometry>
            <cylinder>
              <length>0.15</length>
              <radius>0.01</radius>
            </cylinder>
          </geometry>
          <material>
            <script>
              <name>Gazebo/Grey</name>
              <uri>file://media/materials/scripts/gazebo.material</uri>
            </script>
          </material>
        </visual>
        <visual name='base_link_fixed_joint_lump__laser_frame_visual_2'>
          <pose>0.3 0 0.67 0 -0 0</pose>
          <geometry>
            <cylinder>
              <length>0.04</length>
              <radius>0.05</radius>
            </cylinder>
          </geometry>
          <material>
            <script>
              <name>Gazebo/Black</name>
              <uri>file://media/materials/scripts/gazebo.material</uri>
            </script>
          </material>
        </visual>
        <sensor name='laser' type='ray'>
          <visualize>1</visualize>
          <update_rate>20</update_rate>
          <ray>
            <scan>
              <horizontal>
                <samples>360</samples>
                <min_angle>-3.14</min_angle>
                <max_angle>3.14</max_angle>
                <resolution>1</resolution>
              </horizontal>
              <vertical>
                <samples>1</samples>
                <min_angle>0</min_angle>
                <max_angle>0</max_angle>
              </vertical>
            </scan>
            <range>
              <min>0.3</min>
              <max>12</max>
            </range>
          </ray>
          <plugin name='laser_controller' filename='libgazebo_ros_ray_sensor.so'>
            <ros>
              <argument>~/out:=scan</argument>
            </ros>
            <output_type>sensor_msgs/LaserScan</output_type>
            <frame_name>laser_frame</frame_name>
          </plugin>
          <pose>0.3 0 0.65 0 -0 0</pose>
        </sensor>
        <self_collide>0</self_collide>
        <enable_wind>0</enable_wind>
        <kinematic>0</kinematic>
      </link>
      <joint name='left_back_steering_joint' type='revolute'>
        <pose relative_to='base_link'>-0.5 0.4 0.25 0 -0 0</pose>
        <parent>base_link</parent>
        <child>left_back_steering_link</child>
        <axis>
          <xyz>0 0 1</xyz>
          <limit>
            <lower>-1e+16</lower>
            <upper>1e+16</upper>
          </limit>
          <dynamics>
            <spring_reference>0</spring_reference>
            <spring_stiffness>0</spring_stiffness>
          </dynamics>
        </axis>
      </joint>
      <link name='left_back_steering_link'>
        <pose relative_to='left_back_steering_joint'>0 0 0 0 -0 0</pose>
        <inertial>
          <pose>0 0 0 0 -0 0</pose>
          <mass>0.25</mass>
          <inertia>
            <ixx>0.0025</ixx>
            <ixy>0</ixy>
            <ixz>0</ixz>
            <iyy>0.0025</iyy>
            <iyz>0</iyz>
            <izz>0.00125</izz>
          </inertia>
        </inertial>
        <collision name='left_back_steering_link_collision'>
          <pose>0 0 0 0 -0 0</pose>
          <geometry>
            <cylinder>
              <length>0.3</length>
              <radius>0.1</radius>
            </cylinder>
          </geometry>
          <surface>
            <contact>
              <ode/>
            </contact>
            <friction>
              <ode/>
              <torsional>
                <ode/>
              </torsional>
            </friction>
            <bounce/>
          </surface>
          <max_contacts>10</max_contacts>
        </collision>
        <visual name='left_back_steering_link_visual'>
          <pose>0 0 0 0 -0 0</pose>
          <geometry>
            <cylinder>
              <length>0.3</length>
              <radius>0.1</radius>
            </cylinder>
          </geometry>
          <material>
            <script>
              <name>Gazebo/Red</name>
              <uri>file://media/materials/scripts/gazebo.material</uri>
            </script>
          </material>
        </visual>
        <self_collide>0</self_collide>
        <enable_wind>0</enable_wind>
        <kinematic>0</kinematic>
      </link>
      <joint name='left_back_wheel_joint' type='revolute'>
        <pose relative_to='left_back_steering_link'>0 0 -0.15 -1.5708 0 0</pose>
        <parent>left_back_steering_link</parent>
        <child>left_back_wheel_link</child>
        <axis>
          <xyz>0 0 1</xyz>
          <limit>
            <lower>-1e+16</lower>
            <upper>1e+16</upper>
          </limit>
          <dynamics>
            <spring_reference>0</spring_reference>
            <spring_stiffness>0</spring_stiffness>
          </dynamics>
        </axis>
      </joint>
      <link name='left_back_wheel_link'>
        <pose relative_to='left_back_wheel_joint'>0 0 0 0 -0 0</pose>
        <inertial>
          <pose>0 0 0 0 -0 0</pose>
          <mass>0.5</mass>
          <inertia>
            <ixx>0.00447917</ixx>
            <ixy>0</ixy>
            <ixz>0</ixz>
            <iyy>0.00447917</iyy>
            <iyz>0</iyz>
            <izz>0.005625</izz>
          </inertia>
        </inertial>
        <collision name='left_back_wheel_link_collision'>
          <pose>0 0 0 0 -0 0</pose>
          <geometry>
            <cylinder>
              <length>0.2</length>
              <radius>0.15</radius>
            </cylinder>
          </geometry>
          <surface>
            <contact>
              <ode/>
            </contact>
            <friction>
              <ode/>
              <torsional>
                <ode/>
              </torsional>
            </friction>
            <bounce/>
          </surface>
          <max_contacts>10</max_contacts>
        </collision>
        <visual name='left_back_wheel_link_visual'>
          <pose>0 0 0 0 -0 0</pose>
          <geometry>
            <cylinder>
              <length>0.2</length>
              <radius>0.15</radius>
            </cylinder>
          </geometry>
          <material>
            <script>
              <name>Gazebo/Black</name>
              <uri>file://media/materials/scripts/gazebo.material</uri>
            </script>
          </material>
        </visual>
        <self_collide>0</self_collide>
        <enable_wind>0</enable_wind>
        <kinematic>0</kinematic>
      </link>
      <joint name='left_front_steering_joint' type='revolute'>
        <pose relative_to='base_link'>0.5 0.4 0.25 0 -0 0</pose>
        <parent>base_link</parent>
        <child>left_front_steering_link</child>
        <axis>
          <xyz>0 0 1</xyz>
          <limit>
            <lower>-1e+16</lower>
            <upper>1e+16</upper>
          </limit>
          <dynamics>
            <spring_reference>0</spring_reference>
            <spring_stiffness>0</spring_stiffness>
          </dynamics>
        </axis>
      </joint>
      <link name='left_front_steering_link'>
        <pose relative_to='left_front_steering_joint'>0 0 0 0 -0 0</pose>
        <inertial>
          <pose>0 0 0 0 -0 0</pose>
          <mass>0.25</mass>
          <inertia>
            <ixx>0.0025</ixx>
            <ixy>0</ixy>
            <ixz>0</ixz>
            <iyy>0.0025</iyy>
            <iyz>0</iyz>
            <izz>0.00125</izz>
          </inertia>
        </inertial>
        <collision name='left_front_steering_link_collision'>
          <pose>0 0 0 0 -0 0</pose>
          <geometry>
            <cylinder>
              <length>0.3</length>
              <radius>0.1</radius>
            </cylinder>
          </geometry>
          <surface>
            <contact>
              <ode/>
            </contact>
            <friction>
              <ode/>
              <torsional>
                <ode/>
              </torsional>
            </friction>
            <bounce/>
          </surface>
          <max_contacts>10</max_contacts>
        </collision>
        <visual name='left_front_steering_link_visual'>
          <pose>0 0 0 0 -0 0</pose>
          <geometry>
            <cylinder>
              <length>0.3</length>
              <radius>0.1</radius>
            </cylinder>
          </geometry>
          <material>
            <script>
              <name>Gazebo/Red</name>
              <uri>file://media/materials/scripts/gazebo.material</uri>
            </script>
          </material>
        </visual>
        <self_collide>0</self_collide>
        <enable_wind>0</enable_wind>
        <kinematic>0</kinematic>
      </link>
      <joint name='left_front_wheel_joint' type='revolute'>
        <pose relative_to='left_front_steering_link'>0 0 -0.15 -1.5708 0 0</pose>
        <parent>left_front_steering_link</parent>
        <child>left_front_wheel_link</child>
        <axis>
          <xyz>0 0 1</xyz>
          <limit>
            <lower>-1e+16</lower>
            <upper>1e+16</upper>
          </limit>
          <dynamics>
            <spring_reference>0</spring_reference>
            <spring_stiffness>0</spring_stiffness>
          </dynamics>
        </axis>
      </joint>
      <link name='left_front_wheel_link'>
        <pose relative_to='left_front_wheel_joint'>0 0 0 0 -0 0</pose>
        <inertial>
          <pose>0 0 0 0 -0 0</pose>
          <mass>0.5</mass>
          <inertia>
            <ixx>0.00447917</ixx>
            <ixy>0</ixy>
            <ixz>0</ixz>
            <iyy>0.00447917</iyy>
            <iyz>0</iyz>
            <izz>0.005625</izz>
          </inertia>
        </inertial>
        <collision name='left_front_wheel_link_collision'>
          <pose>0 0 0 0 -0 0</pose>
          <geometry>
            <cylinder>
              <length>0.2</length>
              <radius>0.15</radius>
            </cylinder>
          </geometry>
          <surface>
            <contact>
              <ode/>
            </contact>
            <friction>
              <ode/>
              <torsional>
                <ode/>
              </torsional>
            </friction>
            <bounce/>
          </surface>
          <max_contacts>10</max_contacts>
        </collision>
        <visual name='left_front_wheel_link_visual'>
          <pose>0 0 0 0 -0 0</pose>
          <geometry>
            <cylinder>
              <length>0.2</length>
              <radius>0.15</radius>
            </cylinder>
          </geometry>
          <material>
            <script>
              <name>Gazebo/Black</name>
              <uri>file://media/materials/scripts/gazebo.material</uri>
            </script>
          </material>
        </visual>
        <self_collide>0</self_collide>
        <enable_wind>0</enable_wind>
        <kinematic>0</kinematic>
      </link>
      <joint name='right_back_steering_joint' type='revolute'>
        <pose relative_to='base_link'>-0.5 -0.4 0.25 0 -0 0</pose>
        <parent>base_link</parent>
        <child>right_back_steering_link</child>
        <axis>
          <xyz>0 0 1</xyz>
          <limit>
            <lower>-1e+16</lower>
            <upper>1e+16</upper>
          </limit>
          <dynamics>
            <spring_reference>0</spring_reference>
            <spring_stiffness>0</spring_stiffness>
          </dynamics>
        </axis>
      </joint>
      <link name='right_back_steering_link'>
        <pose relative_to='right_back_steering_joint'>0 0 0 0 -0 0</pose>
        <inertial>
          <pose>0 0 0 0 -0 0</pose>
          <mass>0.25</mass>
          <inertia>
            <ixx>0.0025</ixx>
            <ixy>0</ixy>
            <ixz>0</ixz>
            <iyy>0.0025</iyy>
            <iyz>0</iyz>
            <izz>0.00125</izz>
          </inertia>
        </inertial>
        <collision name='right_back_steering_link_collision'>
          <pose>0 0 0 0 -0 0</pose>
          <geometry>
            <cylinder>
              <length>0.3</length>
              <radius>0.1</radius>
            </cylinder>
          </geometry>
          <surface>
            <contact>
              <ode/>
            </contact>
            <friction>
              <ode/>
              <torsional>
                <ode/>
              </torsional>
            </friction>
            <bounce/>
          </surface>
          <max_contacts>10</max_contacts>
        </collision>
        <visual name='right_back_steering_link_visual'>
          <pose>0 0 0 0 -0 0</pose>
          <geometry>
            <cylinder>
              <length>0.3</length>
              <radius>0.1</radius>
            </cylinder>
          </geometry>
          <material>
            <script>
              <name>Gazebo/Red</name>
              <uri>file://media/materials/scripts/gazebo.material</uri>
            </script>
          </material>
        </visual>
        <self_collide>0</self_collide>
        <enable_wind>0</enable_wind>
        <kinematic>0</kinematic>
      </link>
      <joint name='right_back_wheel_joint' type='revolute'>
        <pose relative_to='right_back_steering_link'>0 0 -0.15 -1.5708 0 0</pose>
        <parent>right_back_steering_link</parent>
        <child>right_back_wheel_link</child>
        <axis>
          <xyz>0 0 1</xyz>
          <limit>
            <lower>-1e+16</lower>
            <upper>1e+16</upper>
          </limit>
          <dynamics>
            <spring_reference>0</spring_reference>
            <spring_stiffness>0</spring_stiffness>
          </dynamics>
        </axis>
      </joint>
      <link name='right_back_wheel_link'>
        <pose relative_to='right_back_wheel_joint'>0 0 0 0 -0 0</pose>
        <inertial>
          <pose>0 0 0 0 -0 0</pose>
          <mass>0.5</mass>
          <inertia>
            <ixx>0.00447917</ixx>
            <ixy>0</ixy>
            <ixz>0</ixz>
            <iyy>0.00447917</iyy>
            <iyz>0</iyz>
            <izz>0.005625</izz>
          </inertia>
        </inertial>
        <collision name='right_back_wheel_link_collision'>
          <pose>0 0 0 0 -0 0</pose>
          <geometry>
            <cylinder>
              <length>0.2</length>
              <radius>0.15</radius>
            </cylinder>
          </geometry>
          <surface>
            <contact>
              <ode/>
            </contact>
            <friction>
              <ode/>
              <torsional>
                <ode/>
              </torsional>
            </friction>
            <bounce/>
          </surface>
          <max_contacts>10</max_contacts>
        </collision>
        <visual name='right_back_wheel_link_visual'>
          <pose>0 0 0 0 -0 0</pose>
          <geometry>
            <cylinder>
              <length>0.2</length>
              <radius>0.15</radius>
            </cylinder>
          </geometry>
          <material>
            <script>
              <name>Gazebo/Black</name>
              <uri>file://media/materials/scripts/gazebo.material</uri>
            </script>
          </material>
        </visual>
        <self_collide>0</self_collide>
        <enable_wind>0</enable_wind>
        <kinematic>0</kinematic>
      </link>
      <joint name='right_front_steering_joint' type='revolute'>
        <pose relative_to='base_link'>0.5 -0.4 0.25 0 -0 0</pose>
        <parent>base_link</parent>
        <child>right_front_steering_link</child>
        <axis>
          <xyz>0 0 1</xyz>
          <limit>
            <lower>-1e+16</lower>
            <upper>1e+16</upper>
          </limit>
          <dynamics>
            <spring_reference>0</spring_reference>
            <spring_stiffness>0</spring_stiffness>
          </dynamics>
        </axis>
      </joint>
      <link name='right_front_steering_link'>
        <pose relative_to='right_front_steering_joint'>0 0 0 0 -0 0</pose>
        <inertial>
          <pose>0 0 0 0 -0 0</pose>
          <mass>0.25</mass>
          <inertia>
            <ixx>0.0025</ixx>
            <ixy>0</ixy>
            <ixz>0</ixz>
            <iyy>0.0025</iyy>
            <iyz>0</iyz>
            <izz>0.00125</izz>
          </inertia>
        </inertial>
        <collision name='right_front_steering_link_collision'>
          <pose>0 0 0 0 -0 0</pose>
          <geometry>
            <cylinder>
              <length>0.3</length>
              <radius>0.1</radius>
            </cylinder>
          </geometry>
          <surface>
            <contact>
              <ode/>
            </contact>
            <friction>
              <ode/>
              <torsional>
                <ode/>
              </torsional>
            </friction>
            <bounce/>
          </surface>
          <max_contacts>10</max_contacts>
        </collision>
        <visual name='right_front_steering_link_visual'>
          <pose>0 0 0 0 -0 0</pose>
          <geometry>
            <cylinder>
              <length>0.3</length>
              <radius>0.1</radius>
            </cylinder>
          </geometry>
          <material>
            <script>
              <name>Gazebo/Red</name>
              <uri>file://media/materials/scripts/gazebo.material</uri>
            </script>
          </material>
        </visual>
        <self_collide>0</self_collide>
        <enable_wind>0</enable_wind>
        <kinematic>0</kinematic>
      </link>
      <joint name='right_front_wheel_joint' type='revolute'>
        <pose relative_to='right_front_steering_link'>0 0 -0.15 -1.5708 0 0</pose>
        <parent>right_front_steering_link</parent>
        <child>right_front_wheel_link</child>
        <axis>
          <xyz>0 0 1</xyz>
          <limit>
            <lower>-1e+16</lower>
            <upper>1e+16</upper>
          </limit>
          <dynamics>
            <spring_reference>0</spring_reference>
            <spring_stiffness>0</spring_stiffness>
          </dynamics>
        </axis>
      </joint>
      <link name='right_front_wheel_link'>
        <pose relative_to='right_front_wheel_joint'>0 0 0 0 -0 0</pose>
        <inertial>
          <pose>0 0 0 0 -0 0</pose>
          <mass>0.5</mass>
          <inertia>
            <ixx>0.00447917</ixx>
            <ixy>0</ixy>
            <ixz>0</ixz>
            <iyy>0.00447917</iyy>
            <iyz>0</iyz>
            <izz>0.005625</izz>
          </inertia>
        </inertial>
        <collision name='right_front_wheel_link_collision'>
          <pose>0 0 0 0 -0 0</pose>
          <geometry>
            <cylinder>
              <length>0.2</length>
              <radius>0.15</radius>
            </cylinder>
          </geometry>
          <surface>
            <contact>
              <ode/>
            </contact>
            <friction>
              <ode/>
              <torsional>
                <ode/>
              </torsional>
            </friction>
            <bounce/>
          </surface>
          <max_contacts>10</max_contacts>
        </collision>
        <visual name='right_front_wheel_link_visual'>
          <pose>0 0 0 0 -0 0</pose>
          <geometry>
            <cylinder>
              <length>0.2</length>
              <radius>0.15</radius>
            </cylinder>
          </geometry>
          <material>
            <script>
              <name>Gazebo/Black</name>
              <uri>file://media/materials/scripts/gazebo.material</uri>
            </script>
          </material>
        </visual>
        <self_collide>0</self_collide>
        <enable_wind>0</enable_wind>
        <kinematic>0</kinematic>
      </link>
      <static>0</static>
      <plugin name='gazebo_ros2_control' filename='libgazebo_ros2_control.so'>
        <parameters>/home/fuga1129/aurora_sim_v2/install/aurora_drive/share/aurora_drive/config/controller_4ws.yaml</parameters>
      </plugin>
      <pose>0 0 0 0 -0 0</pose>
    </model>
    <model name='Construction Cone'>
      <link name='link'>
        <collision name='collision'>
          <geometry>
            <mesh>
              <scale>10 10 10</scale>
              <uri>model://construction_cone/meshes/construction_cone.dae</uri>
            </mesh>
          </geometry>
          <max_contacts>10</max_contacts>
          <surface>
            <contact>
              <ode/>
            </contact>
            <bounce/>
            <friction>
              <torsional>
                <ode/>
              </torsional>
              <ode/>
            </friction>
          </surface>
        </collision>
        <visual name='visual'>
          <geometry>
            <mesh>
              <scale>10 10 10</scale>
              <uri>model://construction_cone/meshes/construction_cone.dae</uri>
            </mesh>
          </geometry>
        </visual>
        <self_collide>0</self_collide>
        <inertial>
          <pose>0 0 0 0 -0 0</pose>
          <inertia>
            <ixx>1</ixx>
            <ixy>0</ixy>
            <ixz>0</ixz>
            <iyy>1</iyy>
            <iyz>0</iyz>
            <izz>1</izz>
          </inertia>
          <mass>1</mass>
        </inertial>
        <enable_wind>0</enable_wind>
        <kinematic>0</kinematic>
      </link>
      <pose>1.33116 -0.61934 0 0 -0 0</pose>
    </model>
    <model name='Construction Barrel'>
      <link name='link'>
        <inertial>
          <pose>0 0 0.4 0 -0 0</pose>
          <mass>500</mass>
          <inertia>
            <ixx>51.2096</ixx>
            <iyy>51.2096</iyy>
            <izz>25</izz>
            <ixy>0</ixy>
            <ixz>0</ixz>
            <iyz>0</iyz>
          </inertia>
        </inertial>
        <collision name='collision'>
          <geometry>
            <mesh>
              <uri>model://construction_barrel/meshes/construction_barrel.dae</uri>
            </mesh>
          </geometry>
          <max_contacts>10</max_contacts>
          <surface>
            <contact>
              <ode/>
            </contact>
            <bounce/>
            <friction>
              <torsional>
                <ode/>
              </torsional>
              <ode/>
            </friction>
          </surface>
        </collision>
        <visual name='visual'>
          <geometry>
            <mesh>
              <uri>model://construction_barrel/meshes/construction_barrel.dae</uri>
            </mesh>
          </geometry>
        </visual>
        <self_collide>0</self_collide>
        <enable_wind>0</enable_wind>
        <kinematic>0</kinematic>
      </link>
      <pose>2.0762 0.960425 0 0 -0 0</pose>
    </model>
    <model name='Construction Barrel_0'>
      <link name='link'>
        <inertial>
          <pose>0 0 0.4 0 -0 0</pose>
          <mass>500</mass>
          <inertia>
            <ixx>51.2096</ixx>
            <iyy>51.2096</iyy>
            <izz>25</izz>
            <ixy>0</ixy>
            <ixz>0</ixz>
            <iyz>0</iyz>
          </inertia>
        </inertial>
        <collision name='collision'>
          <geometry>
            <mesh>
              <uri>model://construction_barrel/meshes/construction_barrel.dae</uri>
            </mesh>
          </geometry>
          <max_contacts>10</max_contacts>
          <surface>
            <contact>
              <ode/>
            </contact>
            <bounce/>
            <friction>
              <torsional>
                <ode/>
              </torsional>
              <ode/>
            </friction>
          </surface>
        </collision>
        <visual name='visual'>
          <geometry>
            <mesh>
              <uri>model://construction_barrel/meshes/construction_barrel.dae</uri>
            </mesh>
          </geometry>
        </visual>
        <self_collide>0</self_collide>
        <enable_wind>0</enable_wind>
        <kinematic>0</kinematic>
      </link>
      <pose>-3.72464 3.10032 0 0 -0 0</pose>
    </model>
    <model name='Construction Cone_0'>
      <link name='link'>
        <collision name='collision'>
          <geometry>
            <mesh>
              <scale>10 10 10</scale>
              <uri>model://construction_cone/meshes/construction_cone.dae</uri>
            </mesh>
          </geometry>
          <max_contacts>10</max_contacts>
          <surface>
            <contact>
              <ode/>
            </contact>
            <bounce/>
            <friction>
              <torsional>
                <ode/>
              </torsional>
              <ode/>
            </friction>
          </surface>
        </collision>
        <visual name='visual'>
          <geometry>
            <mesh>
              <scale>10 10 10</scale>
              <uri>model://construction_cone/meshes/construction_cone.dae</uri>
            </mesh>
          </geometry>
        </visual>
        <self_collide>0</self_collide>
        <inertial>
          <pose>0 0 0 0 -0 0</pose>
          <inertia>
            <ixx>1</ixx>
            <ixy>0</ixy>
            <ixz>0</ixz>
            <iyy>1</iyy>
            <iyz>0</iyz>
            <izz>1</izz>
          </inertia>
          <mass>1</mass>
        </inertial>
        <enable_wind>0</enable_wind>
        <kinematic>0</kinematic>
      </link>
      <pose>-4.07859 -0.635914 0 0 -0 0</pose>
    </model>
    <state world_name='default'>
      <sim_time>885 663000000</sim_time>
      <real_time>887 955345959</real_time>
      <wall_time>1765885182 576917049</wall_time>
      <iterations>885663</iterations>
      <model name='Construction Barrel'>
        <pose>2.07618 0.960419 1e-06 2e-06 3e-06 -6e-06</pose>
        <scale>1 1 1</scale>
        <link name='link'>
          <pose>2.07618 0.960419 1e-06 2e-06 3e-06 -6e-06</pose>
          <velocity>0 0 0 0 -0 0</velocity>
          <acceleration>-4.02544 2.62102 -2.0324 2.85498 0.631685 -3.12435</acceleration>
          <wrench>-2012.72 1310.51 -1016.2 0 -0 0</wrench>
        </link>
      </model>
      <model name='Construction Barrel_0'>
        <pose>-3.72465 3.10032 0 0 0 -3e-06</pose>
        <scale>1 1 1</scale>
        <link name='link'>
          <pose>-3.72465 3.10032 0 0 0 -3e-06</pose>
          <velocity>0 0 0 0 -0 0</velocity>
          <acceleration>3.45854 5.74438 4.40609 1.34623 0.77903 3.14097</acceleration>
          <wrench>1729.27 2872.19 2203.04 0 -0 0</wrench>
        </link>
      </model>
      <model name='Construction Cone'>
        <pose>1.33116 -0.61934 -0 0 -1e-06 0</pose>
        <scale>1 1 1</scale>
        <link name='link'>
          <pose>1.33116 -0.61934 -0 0 -1e-06 0</pose>
          <velocity>0 0 0 0 -0 0</velocity>
          <acceleration>-0 0 0.008512 2.58585 -1.13682 -3.14159</acceleration>
          <wrench>-0 0 0.008512 0 -0 0</wrench>
        </link>
      </model>
      <model name='Construction Cone_0'>
        <pose>-4.07859 -0.635914 -0 0 -1e-06 0</pose>
        <scale>1 1 1</scale>
        <link name='link'>
          <pose>-4.07859 -0.635914 -0 0 -1e-06 0</pose>
          <velocity>0 0 0 0 -0 0</velocity>
          <acceleration>-0 0 0.008512 2.58585 -1.13682 -3.14159</acceleration>
          <wrench>-0 0 0.008512 0 -0 0</wrench>
        </link>
      </model>
      <model name='ground_plane'>
        <pose>0 0 0 0 -0 0</pose>
        <scale>1 1 1</scale>
        <link name='link'>
          <pose>0 0 0 0 -0 0</pose>
          <velocity>0 0 0 0 -0 0</velocity>
          <acceleration>0 0 0 0 -0 0</acceleration>
          <wrench>0 0 0 0 -0 0</wrench>
        </link>
      </model>
      <model name='my_bot'>
        <pose>0.280934 1.70232 0.050002 0 -0 0.435608</pose>
        <scale>1 1 1</scale>
        <link name='base_link'>
          <pose>0.280934 1.70232 0.050002 0 -0 0.435608</pose>
          <velocity>-0.001035 0.001979 0.004905 0.008296 0.004061 -1.1e-05</velocity>
          <acceleration>2.85325 -6.83367 6.88825 2.94771 -1.32157 -0.141066</acceleration>
          <wrench>8.73094 -20.911 21.0781 0 -0 0</wrench>
        </link>
        <link name='left_back_steering_link'>
          <pose>-0.341157 1.85398 0.300002 -1.4e-05 -1e-06 0.435609</pose>
          <velocity>0.000145 -0.000326 0.009023 0.004453 0.002253 -0.00321</velocity>
          <acceleration>1.07562 -2.77463 19.317 -1.77665 -1.5632 2.89767</acceleration>
          <wrench>0.268906 -0.693658 4.82926 0 -0 0</wrench>
        </link>
        <link name='left_back_wheel_link'>
          <pose>-0.341156 1.85398 0.150002 1.57084 -0.597178 -2.70601</pose>
          <velocity>-8.2e-05 0.000198 0.009099 -0.002127 0.001817 -0.003669</velocity>
          <acceleration>-0.418953 0.662091 19.4297 1.55747 -0.501952 0.307549</acceleration>
          <wrench>-0.209477 0.331045 9.71486 0 -0 0</wrench>
        </link>
        <link name='left_front_steering_link'>
          <pose>0.565457 2.27594 0.300002 -1.4e-05 -0 0.299152</pose>
          <velocity>0.0001 -0.000419 0.008922 0.005231 0.002846 -0.000873</velocity>
          <acceleration>1.10486 -3.02658 19.259 -0.998663 -0.970511 -1.0483</acceleration>
          <wrench>0.276216 -0.756645 4.81475 0 -0 0</wrench>
        </link>
        <link name='left_front_wheel_link'>
          <pose>0.565457 2.27594 0.150002 -1.57084 -0.6408 0.299178</pose>
          <velocity>-0.000161 -1.7e-05 0.009031 5.4e-05 -6.6e-05 -0.001404</velocity>
          <acceleration>-0.48632 0.208592 19.3893 -2.92115 1.25353 0.113591</acceleration>
          <wrench>-0.24316 0.104296 9.69466 0 -0 0</wrench>
        </link>
        <link name='right_back_steering_link'>
          <pose>-0.003588 1.12869 0.300002 1.2e-05 -0 0.435622</pose>
          <velocity>4e-05 -0.000315 0.001208 0.001926 0.001061 0.000381</velocity>
          <acceleration>0.843663 -2.82328 -5.16184 -1.16251 -0.386192 -2.9365</acceleration>
          <wrench>0.210916 -0.70582 -1.29046 0 -0 0</wrench>
        </link>
        <link name='right_back_wheel_link'>
          <pose>-0.003589 1.12869 0.150002 1.57079 0.550087 -2.70598</pose>
          <velocity>-0.000286 0.000355 0.001204 -0.002382 -0.001601 0.0004</velocity>
          <acceleration>-0.081575 -0.955076 -5.33502 -1.17383 -0.189019 -2.60347</acceleration>
          <wrench>-0.040788 -0.477538 -2.66751 0 -0 0</wrench>
        </link>
        <link name='right_front_steering_link'>
          <pose>0.903026 1.55065 0.300001 -3e-06 0 0.299153</pose>
          <velocity>-6.2e-05 -2.7e-05 0.001063 0.01049 0.004766 -0.000361</velocity>
          <acceleration>0.815818 -2.69467 -5.26345 -2.02296 0.949846 -0.536303</acceleration>
          <wrench>0.203955 -0.673668 -1.31586 0 -0 0</wrench>
        </link>
        <link name='right_front_wheel_link'>
          <pose>0.903025 1.55065 0.150001 1.57073 1.44304 -2.84251</pose>
          <velocity>-0.000472 0.000449 0.001025 -0.002844 -0.003334 -0.000354</velocity>
          <acceleration>-1.06446 1.03401 -5.30967 -0.307776 -0.147811 -0.337546</acceleration>
          <wrench>-0.53223 0.517007 -2.65483 0 -0 0</wrench>
        </link>
      </model>
      <light name='sun'>
        <pose>0 0 10 0 -0 0</pose>
      </light>
    </state>
    <gui fullscreen='0'>
      <camera name='user_camera'>
        <pose>11.0804 4.79989 8.40131 0 0.627643 -2.64699</pose>
        <view_controller>orbit</view_controller>
        <projection_type>perspective</projection_type>
      </camera>
    </gui>
  </world>
</sdf>
